Workbook
Name _GRA1: #REF!
Name _GRA2: #REF!
Name _mes2: #REF!
Name _mes3: #REF!
Name _one1: #REF!
Name _uno1: #REF!
Name ACTIVIDAD: INICIO!$A$641:$A$661
Name activocirculante: #REF!
Name activofijo: #REF!
Name ACTIVOr1: 'R1'!$E$8:$G$17
Name amortizacion: #REF!
Name analisisbalances: INICIO!$A$419:$A$421
Name analisisoperativo: INICIO!#REF!
Name añobalance: 'R1'!$I$6:$M$6
Name arribaa2: '20Ratios'!$A$3:$A$59
Name ARRIBAAR: Análisis!$A$3:$A$76
Name arribaDATOS: DATOS!$A$4:$A$90
Name arribaR1: 'R1'!$A$3:$A$122
Name arribaR2: 'R2'!$A$3:$A$134
Name asistencial: #REF!
Name balance: SB!$J$5:$J$10
Name balances: INICIO!$A$454:$A$490
Name BreakEvenQuantity: #REF!
Name BUSCARMES: #REF!
Name cantidad: #REF!
Name carencia: #REF!
Name carenciaespecial: #REF!
Name cin: #REF!
Name CINCO: #REF!
Name circulante: SB!$F$6:$F$11
Name complementos: #REF!
Name costesalarial: #REF!
Name CRECIMIENTO: INICIO!#REF!
Name cuarto: #REF!
Name cuat: #REF!
Name CUATRO: #REF!
Name datosbalances: INICIO!$A$852:$A$978
Name DEDUCCIONES: #REF!
Name deducciones2: #REF!
Name devengoiva: #REF!
Name discin: #REF!
Name discuat: #REF!
Name disdos: #REF!
Name distres: #REF!
Name disun: #REF!
Name do: #REF!
Name DOS: #REF!
Name ejemplo: #REF!
Name ejercicio: #REF!
Name ejercicios: #REF!
Name EXIGIBLECP: #REF!
Name EXIGIBLELP: #REF!
Name EXTRASALARIALES: #REF!
Name FLUJOSCAJA: INICIO!$A$577:$A$582
Name fondomaniobra: INICIO!$A$535:$A$633
Name FONDOSPROPIOS: #REF!
Name forma: #REF!
Name forma2: #REF!
Name garajetipo: #REF!
Name GARANTIA: INICIO!$A$467:$A$579

Sheet INICIO
D3: Análisis Fácil de los Balances
D4: Análisis fácil de los Estados Financieros - versión 9.0
D5: Denominación : | F5: MiEmpresa | I5: Año más reciente : | K5: 2026
D6: Notas
E14: =YEAR(A16) -> 2026
D15: Libro gratuito para Excel® basado en un original de A.M. Dunyó y R. Zaccaria
A16: =TODAY() -> 46091
D185: Información
D187: Este libro tiene como objetivo facilitar al máximo el análisis de los balances de una empresa
D188: Sus contenidos y explicaciones han sido elaborados desde una perspectiva práctica, nos hemos esforzado en usar
D189: un lenguaje no técnico, con el objetivo de lograr una mayor comprensión de los conceptos por parte de los
D190: usuarios cuya finalidad es usarlos en la vida cotidiana de su empresa.
D191: Por todo ello, es posible que los expertos hallen en nuestros comentarios algunas imperfecciones conceptuales,
D192: les pedimos disculpas y agradeceremos cualquier sugerencia que se nos haga al respecto.
E194: Muchas gracias por vuestra confianza,
F195: Los autores
D199: Recomendaciones
E201: Recomendaciones para el uso del libro:
E202: ● Pon tus datos en la hoja DATOS, tiene tres secciones numeradas del 1 al 3 (scroll abajo).
E203: ● Una vez hecho lo anterior y con los datos completos, informes, ratios y gráficos se autogenerarán en
E204: las hojas siguientes.
E206: Ten en cuenta:
E207: ● Puedes analizar desde un solo balance hasta un máximo de 5, no es preciso incluir datos en todas
E208: las columnas. Usa sólo las que precises.
E209: ● No es obligatorio incluir todos los datos (aunque siempre es lo mejor), la hoja calculará los ratios que
E210: pueda en función de los datos incluidos.
E211: ● En su versión libre: El libro es totalmente* adaptable y modificable, todas las fórmulas son fácilmente
E212: accesibles y la mayoría han sido agrupadas en una hoja oculta (Calc1) para facilitar el trabajo. Para cambiar o
E213: verificar las fórmulas sólo tienes que mostrar dicha hoja. | I213: Pídenos la versión libre: atención@e.ditor.com
E215: ● En general:
E216: - Las celdas donde debes o puedes introducir datos tienen fondo blanco.
E217: - Los datos que puedas encontrar son totalmente aleatorios, bórralos antes de comenzar.
E218: - Antes de ponerte a trabajar, haz una copia del fichero original y guárdala, así lo tendrás
E219: siempre disponible.
E220: - La mayoría de cabeceras de fila o columna (en las hojas operativas) incluyen explicaciones y comentarios,
E221: para verlos sólo tienes que seleccionar la celda.
E223: * Excepto ésta y la hoja SB (que no afectan de modo relevante a la programación y pueden ser ocultadas)
D225: Producto y derechos
D227: El usuario de este libro para Excel© puede usarlo, modificarlo o copiarlo cuanto desee para su uso personal
D228: o profesional, puede distribuir cuantas copias quiera pero en ningún caso puede comerciar
...

Sheet DATOS
C3: DATOS DE LOS BALANCES
C6: 1 | D6: ACTIVO | H6: =INICIO!$K$5 -> 2026 | I6: =INICIO!K5-1 -> 2025 | J6: =I6-1 -> 2024 | K6: =J6-1 -> 2023 | L6: =K6-1 -> 2022
D7: A- ACTIVO NO CORRIENTE / ACTIVO FIJO | H7: =SUM(H8:H13) -> 0 | I7: =SUM(I8:I13) -> 488501.6 | J7: =SUM(J8:J13) -> 390976.58 | K7: =SUM(K8:K13) -> 146052.87 | L7: =SUM(L8:L13) -> 61147.98
D8: I. Inmovilizado intangible. | I8: 6229.2 | J8: 11013.6 | K8: 15798 | L8: 0
D9: II. Inmovilizado material. | I9: 479272.4 | J9: 376962.98 | K9: 130254.87 | L9: 61147.98
D10: III. Inversiones inmobiliarias. | I10: 0 | J10: 0 | K10: 0 | L10: 0
D11: IV. Inversiones en empresas del grupo y asociadas a largo plazo | I11: 0 | J11: 0 | K11: 0 | L11: 0
D12: V. Inversiones financieras a largo plazo. | I12: 3000 | J12: 3000 | K12: 0 | L12: 0
D13: VI. Activos por impuesto diferido. | I13: 0 | J13: 0 | K13: 0 | L13: 0
D14: B - ACTIVO CORRIENTE /ACTIVO CIRCULANTE | H14: =SUM(H15:H17)+SUM(H21:H24) -> 0 | I14: =SUM(I15:I17)+SUM(I21:I24) -> 843463.59 | J14: =SUM(J15:J17)+SUM(J21:J24) -> 581561.29 | K14: =SUM(K15:K17)+SUM(K21:K24) -> 480210.23 | L14: =SUM(L15:L17)+SUM(L21:L24) -> 292368.73
D15: I. Activos no corrientes mantenidos para la venta. | I15: 0 | J15: 0 | K15: 0 | L15: 0
D16: II. Existencias. | I16: 241085.05 | J16: 180801.13 | K16: 171516.07 | L16: 117928.7
D17: III. Deudores comerciales y otras cuentas a cobrar. | H17: =SUM(H18:H20) -> 0 | I17: =SUM(I18:I20) -> 529680.41 | J17: =SUM(J18:J20) -> 319077.91 | K17: =SUM(K18:K20) -> 237479.15 | L17: =SUM(L18:L20) -> 148953.06
D18: 1. Clientes por ventas y prestaciones de servicios | I18: 529680.41 | J18: 305951.02 | K18: 237479.15 | L18: 133438.68
D19: 2. Accionistas (socios) por desembolsos exigidos | I19: 0 | J19: 0 | K19: 0 | L19: 0
D20: 3. Otros deudores. | I20: 0 | J20: 13126.89 | K20: 0 | L20: 15514.38
D21: IV. Inversiones en empresas del grupo y asociadas a corto plazo | I21: 0 | J21: 0 | K21: 0 | L21: 0
D22: V. Inversiones financieras a corto plazo. | I22: 0 | J22: 0 | K22: 0 | L22: 0
D23: VI. Periodificaciones a corto plazo. | I23: 0 | J23: 0 | K23: 0 | L23: 739.94
D24: VII. Efectivo y otros activos líquidos equivalentes. | I24: 72698.13 | J24: 81682.25 | K24: 71215.01 | L24: 24747.03
D25: Total Activo | H25: =+H7+H14 -> 0 | I25: =+I7+I14 -> 1331965.2 | J25: =+J7+J14 -> 972537.87 | K25: =+K7+K14 -> 626263.1 | L25: =+L7+L14 -> 353516.71
C27: 2 | D27: PATRIMONIO NETO Y PASIVO | H27: =INICIO!K5 -> 2026 | I27: =I6 -> 2025 | J27: =J6 -> 2024 | K27: =K6 -> 2023 | L27: =L6 -> 2022
D28: A) PATRIMONIO NETO | H28: =SUM(H33:H42)+H30 -> 0 | I28: =SUM(I33:I42)+I30 -> 480121.58 | J28: =SUM(J33:J42)+J30 -> 312289.69 | K28: =SUM(K33:K42)+K30 -> 169493.1 | L28: =SUM(L33:L42)+L30 -> 113234.22
D29: A-1) Fondos propios.
D30: I. Capital. | H30: =SUM(H31:H32) -> 0 | I30: =SUM(I31:I32) -> 24000 | J30: =SUM(J31:J32) -> 24000 | K30: =SUM(K31:K32) -> 24000 | L30: =SUM(L31:L32) -> 24000
D31: 1. Capital escriturado. | I31: 24000 | J31: 24000 | K31: 24000 | L31: 24000
D32: 2. (Capital no exigido). | I32: 0 | J32: 0 | K32: 0 | L32: 0
D33: II. Prima de emisión. | I33: 0 | J33: 0 | K33: 0 | L33: 0
D34: III. Reservas. | I34: 288289.69 | J34: 144506.82 | K34: 89234.22 | L34: 68188.79
D35: IV. (Acciones y participaciones en patrimonio propias). | I35: 0 | J35: 0 | K35: 0 | L35: 0
D36: V. Resultados de ejercicios anteriores. | I36: 0 | J36: 0 | K36: 0 | L36: 0
D37: VI. Otras aportaciones de socios. | I37: 0 | J37: 0 | K37: 0 | L37: 0
D38: VII. Resultado del ejercicio. | I38: 167831.89 | J38: 143782.87 | K38: 56258.88 | L38: 21045.43
D39: VIII. (Dividendo a cuenta). | I39: 0 | J39: 0 | K39: 0 | L39: 0
D40: IX. Otros instrumentos de patrimonio neto. | I40: 0 | J40: 0 | K40: 0 | L40: 0
D41: A-2) Ajustes por cambios de valor. | I41: 0 | J41: 0 | K41: 0 | L41: 0
D42: A-3) Subvenciones, donaciones y legados recibidos. | I42: 0 | J42: 0 | K42: 0 | L42: 0
D43: B) PASIVO NO CORRIENTE | H43: =SUM(H49:H51)+H45+H44 -> 0 | I43: =SUM(I49:I51)+I45+I44 -> 251229 | J43: =SUM(J49:J51)+J45+J44 -> 268227.99 | K43: =SUM(K49:K51)+K45+K44 -> 119104.82 | L43: =SUM(L49:L51)+L45+L44 -> 46257.02
D44: I. Provisiones a largo plazo. | I44: 0 | J44: 0 | K44: 0 | L44: 0
D45: II Deudas a largo plazo. | H45: =SUM(H46:H48) -> 0 | I45: =SUM(I46:I48) -> 251229 | J45: =SUM(J46:J48) -> 268227.99 | K45: =SUM(K46:K48) -> 119104.82 | L45: =SUM(L46:L48) -> 46257.02
...

Sheet Calc1
C1: =INICIO!K5 -> 2026 | D1: =DATOS!I6 -> 2025 | E1: =DATOS!J6 -> 2024 | F1: =DATOS!K6 -> 2023 | G1: =DATOS!L6 -> 2022
B2: ACTIVO
B4: Inmovilizado | C4: =+DATOS!H8+DATOS!H9 -> 0 | D4: =+DATOS!I8+DATOS!I9 -> 485501.6 | E4: =+DATOS!J8+DATOS!J9 -> 387976.58 | F4: =+DATOS!K8+DATOS!K9 -> 146052.87 | G4: =+DATOS!L8+DATOS!L9 -> 61147.98
B5: Inversiones | C5: =+DATOS!H10+DATOS!H11+DATOS!H12 -> 0 | D5: =+DATOS!I10+DATOS!I11+DATOS!I12 -> 3000 | E5: =+DATOS!J10+DATOS!J11+DATOS!J12 -> 3000 | F5: =+DATOS!K10+DATOS!K11+DATOS!K12 -> 0 | G5: =+DATOS!L10+DATOS!L11+DATOS!L12 -> 0
B6: Impuestos diferidos | C6: =+DATOS!H13 -> 0 | D6: =+DATOS!I13 -> 0 | E6: =+DATOS!J13 -> 0 | F6: =+DATOS!K13 -> 0 | G6: =+DATOS!L13 -> 0
B7: ACTIVO FIJO | C7: =SUM(C4:C6) -> 0 | D7: =SUM(D4:D6) -> 488501.6 | E7: =SUM(E4:E6) -> 390976.58 | F7: =SUM(F4:F6) -> 146052.87 | G7: =SUM(G4:G6) -> 61147.98
B9: Existencias | C9: =+DATOS!H16+DATOS!H15 -> 0 | D9: =+DATOS!I16+DATOS!I15 -> 241085.05 | E9: =+DATOS!J16+DATOS!J15 -> 180801.13 | F9: =+DATOS!K16+DATOS!K15 -> 171516.07 | G9: =+DATOS!L16+DATOS!L15 -> 117928.7
B10: Clientes | C10: =+DATOS!H18 -> 0 | D10: =+DATOS!I18 -> 529680.41 | E10: =+DATOS!J18 -> 305951.02 | F10: =+DATOS!K18 -> 237479.15 | G10: =+DATOS!L18 -> 133438.68
B11: Inversiones | C11: =+DATOS!H19+DATOS!H20 -> 0 | D11: =+DATOS!I19+DATOS!I20 -> 0 | E11: =+DATOS!J19+DATOS!J20 -> 13126.89 | F11: =+DATOS!K19+DATOS!K20 -> 0 | G11: =+DATOS!L19+DATOS!L20 -> 15514.38
B12: Otras cuentas | C12: =+DATOS!H21+DATOS!H22 -> 0 | D12: =+DATOS!I21+DATOS!I22 -> 0 | E12: =+DATOS!J21+DATOS!J22 -> 0 | F12: =+DATOS!K21+DATOS!K22 -> 0 | G12: =+DATOS!L21+DATOS!L22 -> 0
B13: Periodificaciones | C13: =+DATOS!H23 -> 0 | D13: =+DATOS!I23 -> 0 | E13: =+DATOS!J23 -> 0 | F13: =+DATOS!K23 -> 0 | G13: =+DATOS!L23 -> 739.94
B14: Efectivo y otros liq. | C14: =+DATOS!H24 -> 0 | D14: =+DATOS!I24 -> 72698.13 | E14: =+DATOS!J24 -> 81682.25 | F14: =+DATOS!K24 -> 71215.01 | G14: =+DATOS!L24 -> 24747.03
B15: CIRCULANTE | C15: =SUM(C9:C14) -> 0 | D15: =SUM(D9:D14) -> 843463.59 | E15: =SUM(E9:E14) -> 581561.29 | F15: =SUM(F9:F14) -> 480210.23 | G15: =SUM(G9:G14) -> 292368.73
B16: EXISTENCIAS | C16: =+C9 -> 0 | D16: =+D9 -> 241085.05 | E16: =+E9 -> 180801.13 | F16: =+F9 -> 171516.07 | G16: =+G9 -> 117928.7
B17: REALIZABLE | C17: =+C13+C12+C10+C11 -> 0 | D17: =+D13+D12+D10+D11 -> 529680.41 | E17: =+E13+E12+E10+E11 -> 319077.91 | F17: =+F13+F12+F10+F11 -> 237479.15 | G17: =+G13+G12+G10+G11 -> 149693
B18: DISPONIBLE | C18: =+C14 -> 0 | D18: =+D14 -> 72698.13 | E18: =+E14 -> 81682.25 | F18: =+F14 -> 71215.01 | G18: =+G14 -> 24747.03
B19: TOTAL ACTIVO
C20: =+C15+C7 -> 0 | D20: =+D15+D7 -> 1331965.2 | E20: =+E15+E7 -> 972537.87 | F20: =+F15+F7 -> 626263.1 | G20: =+G15+G7 -> 353516.71
B22: PATRIMONIO NETO
B23: Capital | C23: =+DATOS!H31+DATOS!H32 -> 0 | D23: =+DATOS!I31+DATOS!I32 -> 24000 | E23: =+DATOS!J31+DATOS!J32 -> 24000 | F23: =+DATOS!K31+DATOS!K32 -> 24000 | G23: =+DATOS!L31+DATOS!L32 -> 24000
B24: Otros FP | C24: =+DATOS!H33+DATOS!H34+DATOS!H35+DATOS!H36+DATOS!H37+DATOS!H38+DATOS!H39+DATOS!H40+DATOS!H42 -> 0 | D24: =+DATOS!I33+DATOS!I34+DATOS!I35+DATOS!I36+DATOS!I37+DATOS!I38+DATOS!I39+DATOS!I40+DATOS!I42 -> 456121.58 | E24: =+DATOS!J33+DATOS!J34+DATOS!J35+DATOS!J36+DATOS!J37+DATOS!J38+DATOS!J39+DATOS!J40+DATOS!J42 -> 288289.69 | F24: =+DATOS!K33+DATOS!K34+DATOS!K35+DATOS!K36+DATOS!K37+DATOS!K38+DATOS!K39+DATOS!K40+DATOS!K42 -> 145493.1 | G24: =+DATOS!L33+DATOS!L34+DATOS!L35+DATOS!L36+DATOS!L37+DATOS!L38+DATOS!L39+DATOS!L40+DATOS!L42 -> 89234.22
B25: Ajustes | C25: =+DATOS!H41 -> 0 | D25: =+DATOS!I41 -> 0 | E25: =+DATOS!J41 -> 0 | F25: =+DATOS!K41 -> 0 | G25: =+DATOS!L41 -> 0
B26: PAT. NETO | C26: =SUM(C23:C25) -> 0 | D26: =SUM(D23:D25) -> 480121.58 | E26: =SUM(E23:E25) -> 312289.69 | F26: =SUM(F23:F25) -> 169493.1 | G26: =SUM(G23:G25) -> 113234.22
B28: EXIGIBLE A LARGO PLAZO
B29: Provisiones | C29: =+DATOS!H44 -> 0 | D29: =+DATOS!I44 -> 0 | E29: =+DATOS!J44 -> 0 | F29: =+DATOS!K44 -> 0 | G29: =+DATOS!L44 -> 0
B30: Préstamos largo pl. | C30: =+DATOS!H46+DATOS!H47 -> 0 | D30: =+DATOS!I46+DATOS!I47 -> 251229 | E30: =+DATOS!J46+DATOS!J47 -> 268227.99 | F30: =+DATOS!K46+DATOS!K47 -> 119104.82 | G30: =+DATOS!L46+DATOS!L47 -> 46257.02
B31: Otras deudas | C31: =+DATOS!H48+DATOS!H49 -> 0 | D31: =+DATOS!I48+DATOS!I49 -> 0 | E31: =+DATOS!J48+DATOS!J49 -> 0 | F31: =+DATOS!K48+DATOS!K49 -> 0 | G31: =+DATOS!L48+DATOS!L49 -> 0
B32: Peridificaciones-i.d. | C32: =+DATOS!H50+DATOS!H51 -> 0 | D32: =+DATOS!I50+DATOS!I51 -> 0 | E32: =+DATOS!J50+DATOS!J51 -> 0 | F32: =+DATOS!K50+DATOS!K51 -> 0 | G32: =+DATOS!L50+DATOS!L51 -> 0
B33: EXIGIBLE A LARGO PLAZO | C33: =SUM(C29:C32) -> 0 | D33: =SUM(D29:D32) -> 251229 | E33: =SUM(E29:E32) -> 268227.99 | F33: =SUM(F29:F32) -> 119104.82 | G33: =SUM(G29:G32) -> 46257.02
B35: EXIGIBLE A CORTO PLAZO
B36: Provisiones | C36: =+DATOS!H54 -> 0 | D36: =+DATOS!I54 -> 0 | E36: =+DATOS!J54 -> 0 | F36: =+DATOS!K54 -> 0 | G36: =+DATOS!L54 -> 0
B37: Préstamos corto pl. | C37: =+DATOS!H56+DATOS!H57 -> 0 | D37: =+DATOS!I56+DATOS!I57 -> 54992.23 | E37: =+DATOS!J56+DATOS!J57 -> 38056.64 | F37: =+DATOS!K56+DATOS!K57 -> 10981.32 | G37: =+DATOS!L56+DATOS!L57 -> 12579.79
B38: Otras deudas corto | C38: =+DATOS!H53+DATOS!H58 -> 0 | D38: =+DATOS!I53+DATOS!I58 -> 0 | E38: =+DATOS!J53+DATOS!J58 -> 0 | F38: =+DATOS!K53+DATOS!K58 -> 2444.88 | G38: =+DATOS!L53+DATOS!L58 -> 22312.62
B39: Proveedores | C39: =+DATOS!H61 -> 0 | D39: =+DATOS!I61 -> 349895.8 | E39: =+DATOS!J61 -> 163816.48 | F39: =+DATOS!K61 -> 173138.93 | G39: =+DATOS!L61 -> 83686.94
B40: Otras cuentas pagar | C40: =+DATOS!H62+DATOS!H59 -> 0 | D40: =+DATOS!I62+DATOS!I59 -> 195726.58 | E40: =+DATOS!J62+DATOS!J59 -> 190147.07 | F40: =+DATOS!K62+DATOS!K59 -> 151118.05 | G40: =+DATOS!L62+DATOS!L59 -> 75446.12
B41: Periodificaciones | C41: =+DATOS!H63 -> 0 | D41: =+DATOS!I63 -> 0 | E41: =+DATOS!J63 -> 0 | F41: =+DATOS!K63 -> 0 | G41: =+DATOS!L63 -> 0
B42: EXIGIBLE A CORTO PLAZO | C42: =SUM(C36:C41) -> 0 | D42: =SUM(D36:D41) -> 600614.61 | E42: =SUM(E36:E41) -> 392020.19 | F42: =SUM(F36:F41) -> 337683.18 | G42: =SUM(G36:G41) -> 194025.47
B44: TOTAL PASIVOS | C44: =+C42+C33 -> 0 | D44: =+D42+D33 -> 851843.61 | E44: =+E42+E33 -> 660248.18 | F44: =+F42+F33 -> 456788 | G44: =+G42+G33 -> 240282.49
B45: TOT PN+ PASIVO
B46: TOT PN+ PASIVO | C46: =+C44+C26 -> 0 | D46: =+D44+D26 -> 1331965.2 | E46: =+E44+E26 -> 972537.87 | F46: =+F44+F26 -> 626281.1 | G46: =+G44+G26 -> 353516.71
...

Sheet Análisis
K2: ANÁLISIS de 4 PUNTOS CLAVE | L2: =IF(F4=0,"","Referidos al Balance del") -> Referidos al Balance del | P2: =$F$4 -> 2022
E4: Balance a analizar | F4: 2022 | G4: =IF(F4=0,"◄ Pon el balance que quieres analizar (lista)","") | N4: =$E$20
J6: Análisis rápido de 4 puntos clave
C7: 1 | D7: ACTIVO
E8: ='R1'!$E$8 -> TOTAL ACTIVO | F8: =SUMIF(añobalance,$F$4,'R1'!I8:M8) -> 353516.71
E9: ='R1'!$E$9 -> Activo FIJO | F9: =SUMIF(añobalance,$F$4,'R1'!I9:M9) -> 61147.98 | G9: =IF(F$8=0,0,F9/F$8) -> 0.17297055 | J9: 1- LIQUIDEZ | N9: 3- ENDEUDAMIENTO
E10: ='R1'!$E$11 -> Activo CIRCULANTE | F10: =SUMIF(añobalance,$F$4,'R1'!I11:M11) -> 292368.73 | G10: =IF(F$8=0,0,F10/F$8) -> 0.82702945 | J10: =IF(K10>0,"El circulante es","") -> El circulante es | K10: =$G$328 -> 1.5068575 | L10: =IF(K10>0,"veces el exigible a corto","") -> veces el exigible a corto | N10: =IF(O10>0,"Tiene un ratio","") -> Tiene un ratio | O10: =SUMIF('R2'!$I$6:$M$6,$F$4,'R2'!I22:M22) -> 2.1219954 | P10: =IF(O10>0,"(ratio ENDEUDAMIENTO)","") -> (ratio ENDEUDAMIENTO)
E11: ='R1'!$E$12 -> Existencias | F11: =SUMIF(añobalance,$F$4,'R1'!I12:M12) -> 117928.7 | G11: =IF(F$8=0,0,F11/F$8) -> 0.33358734 | J11: =IF(K10=0,0,IF(G328<=F331,G331,IF(G328>=F332,G332,G330))) -> Precaución, parece INSUFICIENTE | N11: =IF(O10=0,0,IF(G346>=F348,G348,IF(G346<=F349,G349,G347))) -> Precaución, parece EXCESIVO
E12: ='R1'!$E$14 -> Realizable | F12: =SUMIF(añobalance,$F$4,'R1'!I14:M14) -> 149693 | G12: =IF(F$8=0,0,F12/F$8) -> 0.42343967 | J12: =IF(K12>0,"El R + D es","") -> El R + D es | K12: =$G$335 -> 0.89905738 | L12: =IF(K12>0,"veces el exigible a corto","") -> veces el exigible a corto | N12: =IF(N11=0,0,"Analizar ratios endeudamiento (ir a 20Ratios)") -> Analizar ratios endeudamiento (ir a 20Ratios)
E13: ='R1'!$E$16 -> Disponible | F13: =SUMIF(añobalance,$F$4,'R1'!I16:M16) -> 24747.03 | G13: =IF(F$8=0,0,F13/F$8) -> 0.070002434 | J13: =IF(K12=0,0,IF(G335<=F338,G338,IF(G335>=F339,G339,G337))) -> Precaución, parece INSUFICIENTE
J14: =IF(J13=0,0,"Analizar los ratios de liquidez (hoja 20ratios)") -> Analizar los ratios de liquidez (hoja 20ratios)
C15: 2 | D15: Patrimonio Neto y PASIVO | E15: PAT. NETO y PASIVO
E16: ='R1'!E21 -> TOTAL | F16: =SUMIF(añobalance,$F$4,'R1'!I21:M21) -> 353516.71 | J16: 2- CAPITALIZACIÓN | N16: 4- GARANTÍA
E17: ='R1'!E22 -> PATRIMONIO NETO | F17: =SUMIF(añobalance,$F$4,'R1'!I22:M22) -> 113234.22 | G17: =IF(F$16=0,0,F17/F$16) -> 0.32030797 | J17: =IF(K17>0,"El P. Neto es el","") -> El P. Neto es el | K17: =$G$341 -> 0.32030797 | L17: =IF(K17>0,"del total (PN + PASIVO)","") -> del total (PN + PASIVO) | N17: =IF(O17>0,"Tiene un ratio","") -> Tiene un ratio | O17: =SUMIF('R2'!$I$6:$M$6,$F$4,'R2'!I8:M8) -> 0.25448371 | P17: =IF(O17>0,"(ratio GARANTÍA)","") -> (ratio GARANTÍA)
E18: ='R1'!$E$26 -> Pasivo LARGO PLAZO | F18: =SUMIF(añobalance,$F$4,'R1'!I26:M26) -> 46257.02 | G18: =IF(F$16=0,0,F18/F$16) -> 0.13084819 | J18: =IF(K17=0,0,IF(G341<=F343,G343,IF(G341>=F344,G344,G342))) -> Precaución, parece INSUFICIENTE | N18: =IF(O17=0,0,IF(G351<=F353,G353,G352)) -> Precaución, parece INSUFICIENTE
E19: ='R1'!$E$28 -> Pasivo CORTO PLAZO | F19: =SUMIF(añobalance,$F$4,'R1'!I28:M28) -> 194025.47 | G19: =IF(F$16=0,0,F19/F$16) -> 0.54884384 | J19: =IF(J18=0,0,"Analizar los ratios del resumen 1") -> Analizar los ratios del resumen 1 | N19: =IF(N18=0,0,"Analizar los ratios de garantía (hoja 20Ratios)") -> Analizar los ratios de garantía (hoja 20Ratios)
E20: =+H325
E324: parámetros de análisis - NO BORRAR
E325: cuadre del balance | F325: =ROUND(F8,0) -> 353517 | G325: =ROUND(F16,0) -> 353517 | H325: =IF(F325=G325,"","EL BALANCE NO CUADRA")
E327: comparación circulantes | G327: ratio
E328: activo | F328: =+F10 -> 292368.73 | G328: =IF(F329=0,0,F328/F329) -> 1.5068575
E329: pasivo | F329: =+F19 -> 194025.47
E330: RATIO CORRECTO: | F330: 2 | G330: Parece CORRECTO.
E331: ALARMA POR DEBAJO: | F331: 1.8 | G331: Precaución, parece INSUFICIENTE
E332: ALARMA POR ENCIMA: | F332: 2.2 | G332: Atención, parece EXCESIVO.
E334: análisis DISPONIBILIDAD | G334: ratio
E335: Realizable más disponible | F335: =+F12+F13 -> 174440.03 | G335: =IF(F336=0,0,F335/F336) -> 0.89905738
E336: Exigible corto plazo | F336: =+F329 -> 194025.47
E337: RATIO CORRECTO: | F337: 1 | G337: Parece CORRECTO.
E338: ALARMA POR DEBAJO: | F338: 0.95 | G338: Precaución, parece INSUFICIENTE
E339: ALARMA POR ENCIMA: | F339: 1.1 | G339: Atención, parece EXCESIVO.
G340: ratio
E341: análisis CAPITALIZACIÓN | G341: =$G$17 -> 0.32030797
E342: CORRECTO | F342: 40-50% | G342: Parece CORRECTO.
E343: ALARMA POR DEBAJO: | F343: 0.39 | G343: Precaución, parece INSUFICIENTE
E344: ALARMA POR ENCIMA: | F344: 0.51 | G344: Atención, parece EXCESIVO.
G345: ratio
E346: análisis ENDEUDAMIENTO | G346: =$O$10 -> 2.1219954
E347: CORRECTO | F347: 1 | G347: Parece CORRECTO.
E348: Demasiado endeudamiento | F348: 1.1 | G348: Precaución, parece EXCESIVO
...

Sheet 20Ratios
C2: ANÁLISIS 20 RATIOS
D4: Período | E4: =INICIO!K5 -> 2026 | F4: =DATOS!I6 -> 2025 | G4: =DATOS!J6 -> 2024 | H4: =DATOS!K6 -> 2023 | I4: =DATOS!L6 -> 2022 | L4: Criterio general para el análisis (tomarlo con precaución)
C6: 1 | D6: RENTABILIDAD
D7: Rentabilidad Financiera | E7: =Calc1!C78 -> 0 | F7: =Calc1!D78 -> 0.34956123 | G7: =Calc1!E78 -> 0.46041504 | H7: =Calc1!F78 -> 0.33192431 | I7: =Calc1!G78 -> 0.18585751 | L7: % Rentabilidad neta sobre recursos propios (PN).
D8: Rentabilidad Económica | E8: =Calc1!C79 -> 0 | F8: =Calc1!D79 -> 0.12600321 | G8: =Calc1!E79 -> 0.14784295 | H8: =Calc1!F79 -> 0.08983266 | I8: =Calc1!G79 -> 0.059531641 | L8: % Rentabilidad neta sobre total activos.
D9: Rentabilidad del Capital | E9: =Calc1!C80 -> 0 | F9: =Calc1!D80 -> 6.9929954 | G9: =Calc1!E80 -> 5.9909529 | H9: =Calc1!F80 -> 2.34412 | I9: =Calc1!G80 -> 0.87689292 | L9: % Rentabilidad neta sobre el capital social.
D10: Rentabilidad de las Ventas | E10: =Calc1!C81 -> 0 | F10: =Calc1!D81 -> 0.076453714 | G10: =Calc1!E81 -> 0.084176472 | H10: =Calc1!F81 -> 0.053108008 | I10: =Calc1!G81 -> 0.039533429 | L10: % Rentabilidad neta sobre total ventas.
C12: 2 | D12: FONDO de MANIOBRA (Capital de trabajo)
D13: Fondo de Maniobra | E13: =Calc1!C54 -> 0 | F13: =Calc1!D54 -> 242848.98 | G13: =Calc1!E54 -> 189541.1 | H13: =Calc1!F54 -> 142527.05 | I13: =Calc1!G54 -> 98343.26 | L13: Diferencia entre el circulante y el exigible al corto. FdM. Siempre debe ser positivo.
D14: Ratio Fondo Maniobra | E14: =Calc1!C60 -> 0 | F14: =Calc1!D60 -> 0.40433412 | G14: =Calc1!E60 -> 0.48349831 | H14: =Calc1!F60 -> 0.42207329 | I14: =Calc1!G60 -> 0.50685748 | L14: Proporción de FdM respecto al exigible al corto. En general 0,5 es aceptable.
D15: Ratio FdM en días | E15: =Calc1!C61 -> 0 | F15: =Calc1!D61 -> 39.825651 | G15: =Calc1!E61 -> 39.947488 | H15: =Calc1!F61 -> 48.436051 | I15: =Calc1!G61 -> 66.504921 | L15: Días que tarda en regenerarse el FdM con las ventas. Cuanto menos mejor.
C17: 3 | D17: LIQUIDEZ
D18: Liquidez | E18: =Calc1!C56 -> 0 | F18: =Calc1!D56 -> 1.4043341 | G18: =Calc1!E56 -> 1.4834983 | H18: =Calc1!F56 -> 1.4220733 | I18: =Calc1!G56 -> 1.5068575 | L18: Compara el circulante con el exigible a corto. En general: lejos de 1 (cercano a 2).
D19: Tesorería (Acid Test) | E19: =Calc1!C57 -> 0 | F19: =Calc1!D57 -> 1.0029369 | G19: =Calc1!E57 -> 1.0222947 | H19: =Calc1!F57 -> 0.9141532 | I19: =Calc1!G57 -> 0.89905738 | L19: Compara el disponible mas el realizable con el ex. Corto. General: En torno a 1.
D20: Disponibilidad | E20: =Calc1!C58 -> 0 | F20: =Calc1!D58 -> 0.12103956 | G20: =Calc1!E58 -> 0.20836236 | H20: =Calc1!F58 -> 0.21089297 | I20: =Calc1!G58 -> 0.12754527 | L20: Compara el disponible con el exigible al corto. En general: En torno a 0,3.
C22: 4 | D22: ENDEUDAMIENTO y autonomía
D23: Endeudamiento | E23: =Calc1!C63 -> 0 | F23: =Calc1!D63 -> 1.7742248 | G23: =Calc1!E63 -> 2.114217 | H23: =Calc1!F63 -> 2.6950242 | I23: =Calc1!G63 -> 2.1219954 | L23: Compara las deudas con los capitales propios. En general: No mayor que 1.
D24: Endeudamiento Corto Plazo | E24: =Calc1!C64 -> 0 | F24: =Calc1!D64 -> 1.2509636 | G24: =Calc1!E64 -> 1.2553094 | H24: =Calc1!F64 -> 1.9923123 | I24: =Calc1!G64 -> 1.7134879 | L24: Compara las deudas a corto con los capitales propios. Cuanto menor, mejor.
D25: Autonomía | E25: =Calc1!C65 -> 0 | F25: =Calc1!D65 -> 0.56362644 | G25: =Calc1!E65 -> 0.47298834 | H25: =Calc1!F65 -> 0.37105419 | I25: =Calc1!G65 -> 0.47125456 | L25: Similar al de endeudamiento, compara capitales propios con deudas totales
C27: 5 | D27: GARANTÍA y estabilidad
D28: Garantía | E28: =Calc1!C67 -> 0 | F28: =Calc1!D67 -> 0.57346395 | G28: =Calc1!E67 -> 0.59216609 | H28: =Calc1!F67 -> 0.31973885 | I28: =Calc1!G67 -> 0.25448371 | L28: Compara el activo real con el total de las deudas. En general 1,5, no menor.
D29: Consistencia | E29: =Calc1!C68 -> 0 | F29: =Calc1!D68 -> 1.9444475 | G29: =Calc1!E68 -> 1.4576278 | H29: =Calc1!F68 -> 1.2262549 | I29: =Calc1!G68 -> 1.3219178 | L29: Compara el activo fijo con las deudas a largo plazo. En general 2.
D30: Estabilidad | E30: =Calc1!C69 -> 0 | F30: =Calc1!D69 -> 0.6679445 | G30: =Calc1!E69 -> 0.67349642 | H30: =Calc1!F69 -> 0.50607735 | I30: =Calc1!G69 -> 0.38339397 | L30: Compara el activo fijo con los recursos permanentes. En general: menor de 1.
C32: 6 | D32: ROTACIÓN ACTIVOS y días pago/cobro
D33: Rotación activo | E33: =Calc1!C86 -> 0 | F33: =Calc1!D86 -> 1.648098 | G33: =Calc1!E86 -> 1.7563453 | H33: =Calc1!F86 -> 1.6915087 | I33: =Calc1!G86 -> 1.5058557 | L33: Compara el activo con las ventas. Cuanto más alto mejor.
D34: Rotación activo fijo | E34: =Calc1!C87 -> 0 | F34: =Calc1!D87 -> 4.4937603 | G34: =Calc1!E87 -> 4.3688354 | H34: =Calc1!F87 -> 7.2530551 | I34: =Calc1!G87 -> 8.7058505 | L34: Compara las ventas con el activo fijo. Cuanto más alto mejor.
D35: Días cobro clientes | E35: =Calc1!C85 -> 0 | F35: =Calc1!D85 -> 86.864138 | G35: =Calc1!E85 -> 64.481923 | H35: =Calc1!F85 -> 80.704345 | I35: =Calc1!G85 -> 90.238303 | L35: Días que se tarda en cobrar a los clientes. Cuanto menos, mejor.
D36: Días pago proveedores | E36: =Calc1!C84 -> 0 | F36: =Calc1!D84 -> 96.937587 | G36: =Calc1!E84 -> 58.565569 | H36: =Calc1!F84 -> 94.766035 | I36: =Calc1!G84 -> 88.595375 | L36: Días que se tarda en pagar a los proveedores. Cuanto más mejor.

Sheet R1
D2: RESUMEN y GRÁFICOS 1 | K2: Análisis BÁSICO
E4: =INICIO!$F$5 -> MiEmpresa | H4: Análisis de los balances
E6: ACTIVO | I6: =INICIO!K5 -> 2026 | J6: =DATOS!I6 -> 2025 | K6: =DATOS!J6 -> 2024 | L6: =DATOS!K6 -> 2023 | M6: =DATOS!L6 -> 2022
E8: TOTAL ACTIVO | I8: =Calc1!C20 -> 0 | J8: =Calc1!D20 -> 1331965.2 | K8: =Calc1!E20 -> 972537.87 | L8: =Calc1!F20 -> 626263.1 | M8: =Calc1!G20 -> 353516.71
E9: Activo FIJO | I9: =Calc1!C7 -> 0 | J9: =Calc1!D7 -> 488501.6 | K9: =Calc1!E7 -> 390976.58 | L9: =Calc1!F7 -> 146052.87 | M9: =Calc1!G7 -> 61147.98
E10: % vs. Total | I10: =IF(I$8=0,"",I9/I$8) | J10: =IF(J$8=0,"",J9/J$8) -> 0.36675253 | K10: =IF(K$8=0,"",K9/K$8) -> 0.40201682 | L10: =IF(L$8=0,"",L9/L$8) -> 0.23321328 | M10: =IF(M$8=0,"",M9/M$8) -> 0.17297055
E11: Activo CIRCULANTE | I11: =Calc1!C15 -> 0 | J11: =Calc1!D15 -> 843463.59 | K11: =Calc1!E15 -> 581561.29 | L11: =Calc1!F15 -> 480210.23 | M11: =Calc1!G15 -> 292368.73
E12: Existencias | I12: =Calc1!C16 -> 0 | J12: =Calc1!D16 -> 241085.05 | K12: =Calc1!E16 -> 180801.13 | L12: =Calc1!F16 -> 171516.07 | M12: =Calc1!G16 -> 117928.7
E13: % vs. Total | I13: =IF(I$8=0,"",I12/I$8) | J13: =IF(J$8=0,"",J12/J$8) -> 0.18099951 | K13: =IF(K$8=0,"",K12/K$8) -> 0.18590652 | L13: =IF(L$8=0,"",L12/L$8) -> 0.27387223 | M13: =IF(M$8=0,"",M12/M$8) -> 0.33358734
E14: Realizable | I14: =Calc1!C17 -> 0 | J14: =Calc1!D17 -> 529680.41 | K14: =Calc1!E17 -> 319077.91 | L14: =Calc1!F17 -> 237479.15 | M14: =Calc1!G17 -> 149693
E15: % vs. Total | I15: =IF(I$8=0,"",I14/I$8) | J15: =IF(J$8=0,"",J14/J$8) -> 0.39766836 | K15: =IF(K$8=0,"",K14/K$8) -> 0.3280879 | L15: =IF(L$8=0,"",L14/L$8) -> 0.37920029 | M15: =IF(M$8=0,"",M14/M$8) -> 0.42343967
E16: Disponible | I16: =Calc1!C18 -> 0 | J16: =Calc1!D18 -> 72698.13 | K16: =Calc1!E18 -> 81682.25 | L16: =Calc1!F18 -> 71215.01 | M16: =Calc1!G18 -> 24747.03
E17: % vs. Total | I17: =IF(I$8=0,"",I16/I$8) | J17: =IF(J$8=0,"",J16/J$8) -> 0.054579602 | K17: =IF(K$8=0,"",K16/K$8) -> 0.08398876 | L17: =IF(L$8=0,"",L16/L$8) -> 0.1137142 | M17: =IF(M$8=0,"",M16/M$8) -> 0.070002434
E19: Patrimonio NETO y PASIVO | I19: =I6 -> 2026 | J19: =J6 -> 2025 | K19: =K6 -> 2024 | L19: =L6 -> 2023 | M19: =M6 -> 2022
E21: TOTAL | I21: =Calc1!C46 -> 0 | J21: =Calc1!D46 -> 1331965.2 | K21: =Calc1!E46 -> 972537.87 | L21: =Calc1!F46 -> 626281.1 | M21: =Calc1!G46 -> 353516.71
E22: PATRIMONIO NETO | I22: =Calc1!C26 -> 0 | J22: =Calc1!D26 -> 480121.58 | K22: =Calc1!E26 -> 312289.69 | L22: =Calc1!F26 -> 169493.1 | M22: =Calc1!G26 -> 113234.22
E23: % vs. Total | I23: =IF(I$21=0,"",I22/I$21) | J23: =IF(J$21=0,"",J22/J$21) -> 0.36046106 | K23: =IF(K$21=0,"",K22/K$21) -> 0.321108 | L23: =IF(L$21=0,"",L22/L$21) -> 0.27063422 | M23: =IF(M$21=0,"",M22/M$21) -> 0.32030797
E24: CAPITAL | I24: =Calc1!C23 -> 0 | J24: =Calc1!D23 -> 24000 | K24: =Calc1!E23 -> 24000 | L24: =Calc1!F23 -> 24000 | M24: =Calc1!G23 -> 24000
E25: % vs. Total | I25: =IF(I$21=0,"",I24/I$21) | J25: =IF(J$21=0,"",J24/J$21) -> 0.018018489 | K25: =IF(K$21=0,"",K24/K$21) -> 0.024677702 | L25: =IF(L$21=0,"",L24/L$21) -> 0.03832145 | M25: =IF(M$21=0,"",M24/M$21) -> 0.067889294
E26: Pasivo LARGO PLAZO | I26: =Calc1!C33 -> 0 | J26: =Calc1!D33 -> 251229 | K26: =Calc1!E33 -> 268227.99 | L26: =Calc1!F33 -> 119104.82 | M26: =Calc1!G33 -> 46257.02
E27: % vs. Total | I27: =IF(I$21=0,"",I26/I$21) | J27: =IF(J$21=0,"",J26/J$21) -> 0.18861529 | K27: =IF(K$21=0,"",K26/K$21) -> 0.2758021 | L27: =IF(L$21=0,"",L26/L$21) -> 0.19017789 | M27: =IF(M$21=0,"",M26/M$21) -> 0.13084819
E28: Pasivo CORTO PLAZO | I28: =Calc1!C42 -> 0 | J28: =Calc1!D42 -> 600614.61 | K28: =Calc1!E42 -> 392020.19 | L28: =Calc1!F42 -> 337683.18 | M28: =Calc1!G42 -> 194025.47
E29: % vs. Total | I29: =IF(I$21=0,"",I28/I$21) | J29: =IF(J$21=0,"",J28/J$21) -> 0.45092365 | K29: =IF(K$21=0,"",K28/K$21) -> 0.4030899 | L29: =IF(L$21=0,"",L28/L$21) -> 0.53918788 | M29: =IF(M$21=0,"",M28/M$21) -> 0.54884384
E32: VARIACIÓN ANUAL | J32: =J6 -> 2025 | K32: =K6 -> 2024 | L32: =L6 -> 2023 | M32: =M6 -> 2022
E34: ACTIVO | J34: =IF(J8=0,0,IF(I$8=0,0,(J8/I$8)-100%)) -> 0 | K34: =IF(K8=0,0,IF(J$8=0,0,(K8/J$8)-100%)) -> -0.26984738 | L34: =IF(L8=0,0,IF(K$8=0,0,(L8/K$8)-100%)) -> -0.35605274 | M34: =IF(M8=0,0,IF(L$8=0,0,(M8/L$8)-100%)) -> -0.43551407
E35: Activo Fijo | J35: =IF(J9=0,0,IF(I9=0,0,(J9/I9)-100%)) -> 0 | K35: =IF(K9=0,0,IF(J9=0,0,(K9/J9)-100%)) -> -0.19964115 | L35: =IF(L9=0,0,IF(K9=0,0,(L9/K9)-100%)) -> -0.62644087 | M35: =IF(M9=0,0,IF(L9=0,0,(M9/L9)-100%)) -> -0.58132983
E36: Activo Circulante | J36: =IF(J11=0,0,IF(I11=0,0,(J11/I11)-100%)) -> 0 | K36: =IF(K11=0,0,IF(J11=0,0,(K11/J11)-100%)) -> -0.31050813 | L36: =IF(L11=0,0,IF(K11=0,0,(L11/K11)-100%)) -> -0.17427408 | M36: =IF(M11=0,0,IF(L11=0,0,(M11/L11)-100%)) -> -0.39116514
E37: P.N. y PASIVO | J37: =IF(J21=0,0,IF(I21=0,0,(J21/I21)-100%)) -> 0 | K37: =IF(K21=0,0,IF(J21=0,0,(K21/J21)-100%)) -> -0.26984738 | L37: =IF(L21=0,0,IF(K21=0,0,(L21/K21)-100%)) -> -0.35603423 | M37: =IF(M21=0,0,IF(L21=0,0,(M21/L21)-100%)) -> -0.43553029
E38: Patrimonio Neto | J38: =IF(J22=0,0,IF(I22=0,0,(J22/I22)-100%)) -> 0 | K38: =IF(K22=0,0,IF(J22=0,0,(K22/J22)-100%)) -> -0.34956123 | L38: =IF(L22=0,0,IF(K22=0,0,(L22/K22)-100%)) -> -0.45725682 | M38: =IF(M22=0,0,IF(L22=0,0,(M22/L22)-100%)) -> -0.33192431
E39: Pasivo Largo Plazo | J39: =IF(J26=0,0,IF(I26=0,0,(J26/I26)-100%)) -> 0 | K39: =IF(K26=0,0,IF(J26=0,0,(K26/J26)-100%)) -> 0.067663327 | L39: =IF(L26=0,0,IF(K26=0,0,(L26/K26)-100%)) -> -0.55595678 | M39: =IF(M26=0,0,IF(L26=0,0,(M26/L26)-100%)) -> -0.61162764
E40: Pasivo Corto Plazo | J40: =IF(J28=0,0,IF(I28=0,0,(J28/I28)-100%)) -> 0 | K40: =IF(K28=0,0,IF(J28=0,0,(K28/J28)-100%)) -> -0.34730161 | L40: =IF(L28=0,0,IF(K28=0,0,(L28/K28)-100%)) -> -0.13860768 | M40: =IF(M28=0,0,IF(L28=0,0,(M28/L28)-100%)) -> -0.42542157

Sheet R2
D2: RESUMEN y GRÁFICOS 2 | K2: Análisis de RATIOS
E4: =INICIO!$F$5 -> MiEmpresa | I4: Ratios para el análisis
E6: ='20Ratios'!$D$27 -> GARANTÍA y estabilidad | I6: ='R1'!I6 -> 2026 | J6: ='R1'!J6 -> 2025 | K6: ='R1'!K6 -> 2024 | L6: ='R1'!L6 -> 2023 | M6: ='R1'!M6 -> 2022
E8: ='20Ratios'!D28 -> Garantía | I8: ='20Ratios'!E28 -> 0 | J8: ='20Ratios'!F28 -> 0.57346395 | K8: ='20Ratios'!G28 -> 0.59216609 | L8: ='20Ratios'!H28 -> 0.31973885 | M8: ='20Ratios'!I28 -> 0.25448371
E9: ='20Ratios'!D29 -> Consistencia | I9: ='20Ratios'!E29 -> 0 | J9: ='20Ratios'!F29 -> 1.9444475 | K9: ='20Ratios'!G29 -> 1.4576278 | L9: ='20Ratios'!H29 -> 1.2262549 | M9: ='20Ratios'!I29 -> 1.3219178
E10: ='20Ratios'!D30 -> Estabilidad | I10: ='20Ratios'!E30 -> 0 | J10: ='20Ratios'!F30 -> 0.6679445 | K10: ='20Ratios'!G30 -> 0.67349642 | L10: ='20Ratios'!H30 -> 0.50607735 | M10: ='20Ratios'!I30 -> 0.38339397
E13: LIQUIDEZ | I13: =I6 -> 2026 | J13: =J6 -> 2025 | K13: =K6 -> 2024 | L13: =L6 -> 2023 | M13: =M6 -> 2022
E15: ='20Ratios'!D18 -> Liquidez | I15: ='20Ratios'!E18 -> 0 | J15: ='20Ratios'!F18 -> 1.4043341 | K15: ='20Ratios'!G18 -> 1.4834983 | L15: ='20Ratios'!H18 -> 1.4220733 | M15: ='20Ratios'!I18 -> 1.5068575
E16: ='20Ratios'!D19 -> Tesorería (Acid Test) | I16: ='20Ratios'!E19 -> 0 | J16: ='20Ratios'!F19 -> 1.0029369 | K16: ='20Ratios'!G19 -> 1.0222947 | L16: ='20Ratios'!H19 -> 0.9141532 | M16: ='20Ratios'!I19 -> 0.89905738
E17: ='20Ratios'!D20 -> Disponibilidad | I17: ='20Ratios'!E20 -> 0 | J17: ='20Ratios'!F20 -> 0.12103956 | K17: ='20Ratios'!G20 -> 0.20836236 | L17: ='20Ratios'!H20 -> 0.21089297 | M17: ='20Ratios'!I20 -> 0.12754527
E20: ENDEUDAMIENTO | I20: =I13 -> 2026 | J20: =J13 -> 2025 | K20: =K13 -> 2024 | L20: =L13 -> 2023 | M20: =M13 -> 2022
E22: ='20Ratios'!D23 -> Endeudamiento | I22: ='20Ratios'!E23 -> 0 | J22: ='20Ratios'!F23 -> 1.7742248 | K22: ='20Ratios'!G23 -> 2.114217 | L22: ='20Ratios'!H23 -> 2.6950242 | M22: ='20Ratios'!I23 -> 2.1219954
E23: ='20Ratios'!D24 -> Endeudamiento Corto Plazo | I23: ='20Ratios'!E24 -> 0 | J23: ='20Ratios'!F24 -> 1.2509636 | K23: ='20Ratios'!G24 -> 1.2553094 | L23: ='20Ratios'!H24 -> 1.9923123 | M23: ='20Ratios'!I24 -> 1.7134879
E26: RENTABILIDAD | I26: =I13 -> 2026 | J26: =J13 -> 2025 | K26: =K13 -> 2024 | L26: =L13 -> 2023 | M26: =M13 -> 2022
E28: ='20Ratios'!D7 -> Rentabilidad Financiera | I28: ='20Ratios'!E7 -> 0 | J28: ='20Ratios'!F7 -> 0.34956123 | K28: ='20Ratios'!G7 -> 0.46041504 | L28: ='20Ratios'!H7 -> 0.33192431 | M28: ='20Ratios'!I7 -> 0.18585751
E29: ='20Ratios'!D8 -> Rentabilidad Económica | I29: ='20Ratios'!E8 -> 0 | J29: ='20Ratios'!F8 -> 0.12600321 | K29: ='20Ratios'!G8 -> 0.14784295 | L29: ='20Ratios'!H8 -> 0.08983266 | M29: ='20Ratios'!I8 -> 0.059531641
E30: ='20Ratios'!D9 -> Rentabilidad del Capital | I30: ='20Ratios'!E9 -> 0 | J30: ='20Ratios'!F9 -> 6.9929954 | K30: ='20Ratios'!G9 -> 5.9909529 | L30: ='20Ratios'!H9 -> 2.34412 | M30: ='20Ratios'!I9 -> 0.87689292
E31: ='20Ratios'!D10 -> Rentabilidad de las Ventas | I31: ='20Ratios'!E10 -> 0 | J31: ='20Ratios'!F10 -> 0.076453714 | K31: ='20Ratios'!G10 -> 0.084176472 | L31: ='20Ratios'!H10 -> 0.053108008 | M31: ='20Ratios'!I10 -> 0.039533429
E34: FONDO de MANIOBRA | I34: =I26 -> 2026 | J34: =J26 -> 2025 | K34: =K26 -> 2024 | L34: =L26 -> 2023 | M34: =M26 -> 2022
E36: ='20Ratios'!D13 -> Fondo de Maniobra | I36: ='20Ratios'!E13 -> 0 | J36: ='20Ratios'!F13 -> 242848.98 | K36: ='20Ratios'!G13 -> 189541.1 | L36: ='20Ratios'!H13 -> 142527.05 | M36: ='20Ratios'!I13 -> 98343.26
E37: ='20Ratios'!D14 -> Ratio Fondo Maniobra | I37: ='20Ratios'!E14 -> 0 | J37: ='20Ratios'!F14 -> 0.40433412 | K37: ='20Ratios'!G14 -> 0.48349831 | L37: ='20Ratios'!H14 -> 0.42207329 | M37: ='20Ratios'!I14 -> 0.50685748
E38: ='20Ratios'!D15 -> Ratio FdM en días | I38: ='20Ratios'!E15 -> 0 | J38: ='20Ratios'!F15 -> 39.825651 | K38: ='20Ratios'!G15 -> 39.947488 | L38: ='20Ratios'!H15 -> 48.436051 | M38: ='20Ratios'!I15 -> 66.504921
E41: ROTACIÓN ACTIVOS | I41: =I26 -> 2026 | J41: =J26 -> 2025 | K41: =K26 -> 2024 | L41: =L26 -> 2023 | M41: =M26 -> 2022
E43: ='20Ratios'!D33 -> Rotación activo | I43: ='20Ratios'!E33 -> 0 | J43: ='20Ratios'!F33 -> 1.648098 | K43: ='20Ratios'!G33 -> 1.7563453 | L43: ='20Ratios'!H33 -> 1.6915087 | M43: ='20Ratios'!I33 -> 1.5058557
E44: ='20Ratios'!D34 -> Rotación activo fijo | I44: ='20Ratios'!E34 -> 0 | J44: ='20Ratios'!F34 -> 4.4937603 | K44: ='20Ratios'!G34 -> 4.3688354 | L44: ='20Ratios'!H34 -> 7.2530551 | M44: ='20Ratios'!I34 -> 8.7058505
E45: ='20Ratios'!D35 -> Días cobro clientes | I45: ='20Ratios'!E35 -> 0 | J45: ='20Ratios'!F35 -> 86.864138 | K45: ='20Ratios'!G35 -> 64.481923 | L45: ='20Ratios'!H35 -> 80.704345 | M45: ='20Ratios'!I35 -> 90.238303
E46: ='20Ratios'!D36 -> Días pago proveedores | I46: ='20Ratios'!E36 -> 0 | J46: ='20Ratios'!F36 -> 96.937587 | K46: ='20Ratios'!G36 -> 58.565569 | L46: ='20Ratios'!H36 -> 94.766035 | M46: ='20Ratios'!I36 -> 88.595375

Sheet SB
C2: LISTAS DESPLEGABLES
J4: balance
D5: inmovilizado | F5: circulante | H5: patrimonion | J5: =+INICIO!K5 -> 2026
D6: Inmovilizado | F6: Existencias | H6: Capital | J6: =+DATOS!I6 -> 2025
D7: Inversiones | F7: Clientes | H7: Otros FP | J7: =+DATOS!J6 -> 2024
D8: Impuestos diferidos | F8: Otras ctas. cobrar | H8: Ajustes | J8: =+DATOS!K6 -> 2023
F9: Inversiones | J9: =+DATOS!L6 -> 2022
F10: Periodificaciones
F11: Efectivo y otros liq.
D17: pasivocorriente | F17: pasivoNOcorriente
D18: Provisiones | F18: Provisiones | H18: =+TODAY() -> 46091
D19: Préstamos corto pl. | F19: Préstamos largo pl.
D20: Otras deudas corto | F20: Otras deudas
D21: Proveedores | F21: Peridificaciones-i.d.
D22: Otras cuentas pagar
D23: Periodificaciones
H39: =+YEAR(H18) -> 2026
